Workbook

Sheet Start Here
A1: TRILLIONAIRE ME — REQUIREMENTS REGISTER v2.0 (companion to Canonical Spec v2.0)
A3: Field | B3: Meaning
A4: Status | B4: Specification stage. NOTHING is implemented. Every 'Verification' cell = Not verified. No repository, database or app was inspected or built.
A5: Authority | B5: Canonical Spec v2.0 > this Register > v1.x files (history only). Origin tags: U = user's own words · B = user-approved brief · S = original source document (second-hand; 3 originals not attached) · P = later spec/audit rule · I = assistant inference (needs owner confirmation).
A6: Priority (R) | B6: R0 = must pass before the first REAL sensitive data entry or the first external/consequential action that the requirement touches (see 'Must pass before gate'). R1 = must pass before a dependable first release. R2 = later. Separate from v1 'Priority' (kept for history) and from audit severity.
A7: Gate | B7: One vocabulary only: G0 spec freeze · G1 safe shell+field catalog · G2 Android offline prototype · G3 rule-based planner (≈80% without AI) · G4 research/options · G5 Deen content verification · G6 AI/automation · G7 privacy/recovery/real-data · G8 pilot→PC→public decision.
A8: Scope tag | B8: FIRST-BUILD = first needed in G1–G3. FULL-SCOPE, LATER = needed in the full product at the stated later gate. NOTHING is dropped; deferral reasons are in 'Deferrals'.
A9: Intent link | B9: Domain-level default mapping to the Intent Register (INT-xx). To be refined row-by-row at G0; new rows (142+) are mapped individually.
A10: Tests | B10: 'Tests v2' replaces all v1 tests. Each has method, threshold, dataset, blocked-by. Human-review rows are gates, not engineering tests. All status = Not run.
A11: Merged rows | B11: TM-REQ-135 → 126, TM-REQ-141 → 120 (rows kept, marked MERGED, excluded from active counts).
A12: Estimates | B12: Counts on 'Summary' are formulas over 'Requirements v2'. Nothing here is a time/cost estimate.
A13: Sheets | B13: Summary · Requirements v2 · Tests v2 · Intent Register · Gates · Decisions · Deferrals · Conflicts · Visual Refs · Change Log

Sheet Summary
A1: SUMMARY — live counts (formulas over 'Requirements v2')
A2: Active = not merged. Change a row in 'Requirements v2' and these update.
A4: Total rows | B4: =COUNTA('Requirements v2'!A4:A175)
A5: Merged rows | B5: =COUNTIF('Requirements v2'!L4:L175,"MERGED*")
A6: Active rows | B6: =B4-B5
A8: By R-priority (all rows)
A9: R0 | B9: =COUNTIF('Requirements v2'!F4:F175,A9)
A10: R1 | B10: =COUNTIF('Requirements v2'!F4:F175,A10)
A11: R2 | B11: =COUNTIF('Requirements v2'!F4:F175,A11)
A13: By first-needed gate
A14: G0 | B14: =COUNTIF('Requirements v2'!G4:G175,A14)
A15: G1 | B15: =COUNTIF('Requirements v2'!G4:G175,A15)
A16: G2 | B16: =COUNTIF('Requirements v2'!G4:G175,A16)
A17: G3 | B17: =COUNTIF('Requirements v2'!G4:G175,A17)
A18: G4 | B18: =COUNTIF('Requirements v2'!G4:G175,A18)
A19: G5 | B19: =COUNTIF('Requirements v2'!G4:G175,A19)
A20: G6 | B20: =COUNTIF('Requirements v2'!G4:G175,A20)
A21: G7 | B21: =COUNTIF('Requirements v2'!G4:G175,A21)
A22: G8 | B22: =COUNTIF('Requirements v2'!G4:G175,A22)
A24: By must-pass gate
A25: G0 | B25: =COUNTIF('Requirements v2'!H4:H175,A25)
A26: G1 | B26: =COUNTIF('Requirements v2'!H4:H175,A26)
A27: G2 | B27: =COUNTIF('Requirements v2'!H4:H175,A27)
A28: G3 | B28: =COUNTIF('Requirements v2'!H4:H175,A28)
A29: G4 | B29: =COUNTIF('Requirements v2'!H4:H175,A29)
A30: G5 | B30: =COUNTIF('Requirements v2'!H4:H175,A30)
A31: G6 | B31: =COUNTIF('Requirements v2'!H4:H175,A31)
A32: G7 | B32: =COUNTIF('Requirements v2'!H4:H175,A32)
A33: G8 | B33: =COUNTIF('Requirements v2'!H4:H175,A33)
A35: By origin (rows containing tag)
A36: U | B36: =COUNTIF('Requirements v2'!D4:D175,"*"&A36&"*")
A37: B | B37: =COUNTIF('Requirements v2'!D4:D175,"*"&A37&"*")
A38: S | B38: =COUNTIF('Requirements v2'!D4:D175,"*"&A38&"*")
A39: P | B39: =COUNTIF('Requirements v2'!D4:D175,"*"&A39&"*")
A40: I | B40: =COUNTIF('Requirements v2'!D4:D175,"*"&A40&"*")
A42: Scope: FIRST-BUILD (G1–G3 start) | B42: =COUNTIF('Requirements v2'!I4:I175,"FIRST-BUILD*")
A43: Scope: FULL-SCOPE, LATER | B43: =COUNTIF('Requirements v2'!I4:I175,"FULL-SCOPE*")
A44: Implemented (verified) | B44: =COUNTIF('Requirements v2'!O4:O175,"Verified*")
A46: Note: origin counts overlap (a row can carry two tags). 'Implemented' = 0 by design at specification stage.

Sheet Requirements v2
A1: REQUIREMENTS v2 — 172 rows (170 active, 2 merged)
A2: Filter by Gate / R / Origin / Domain. 'Implementation verification' = Not verified for all rows.
A3: Req ID | B3: Domain | C3: Requirement | D3: Origin | E3: Intent link | F3: R (v2) | G3: First needed gate | H3: Must pass before gate | I3: Scope tag | J3: v1 priority | K3: v1 coverage status | L3: Merge / cross-link | M3: Blocked by decision | N3: Test ID | O3: Implementation verification
A4: TM-REQ-001 | B4: Governance & outcomes | C4: Define what “Trillionaire” means for each target | D4: P+B | E4: INT-27,INT-09 | F4: R0 | G4: G1 | H4: G3 | I4: FIRST-BUILD (G1-G3) | J4: P0 | K4: Decision required | N4: TM-TST-001 | O4: Not verified — no build
A5: TM-REQ-002 | B5: Governance & outcomes | C5: Keep multiple north-star outcomes separate | D5: P | E5: INT-27,INT-09 | F5: R0 | G5: G1 | H5: G3 | I5: FIRST-BUILD (G1-G3) | J5: P0 | K5: Partial—gap remains | N5: TM-TST-002 | O5: Not verified — no build
A6: TM-REQ-003 | B6: Governance & outcomes | C6: Respect the user's value hierarchy, including Deen/Akhirah | D6: U+B | E6: INT-27,INT-09 | F6: R1 | G6: G1 | H6: G3 | I6: FIRST-BUILD (G1-G3) | J6: P0 | K6: Documented—implementation unverified | N6: TM-TST-003 | O6: Verified for G1 scope (automated evidence) — see Tests v2
A7: TM-REQ-004 | B7: Governance & outcomes | C7: Do not guarantee extreme wealth, investment returns or success | D7: P | E7: INT-27,INT-09 | F7: R0 | G7: G1 | H7: G3 | I7: FIRST-BUILD (G1-G3) | J7: P0 | K7: Documented—implementation unverified | N7: TM-TST-004 | O7: Not verified — no build
A8: TM-REQ-005 | B8: Governance & outcomes | C8: Treat old starting cash as an unverified historical claim | D8: P | E8: INT-27,INT-09 | F8: R0 | G8: G0 | H8: G1 | I8: FIRST-BUILD (G1-G3) | J8: P0 | K8: Source conflict / stale-risk | N8: TM-TST-005 | O8: Not verified — no build
A9: TM-REQ-006 | B9: Governance & outcomes | C9: Separate facts, estimates, assumptions, inferences and external evidence | D9: P | E9: INT-27,INT-09 | F9: R0 | G9: G1 | H9: G1 | I9: FIRST-BUILD (G1-G3) | J9: P0 | K9: Documented—implementation unverified | N9: TM-TST-006 | O9: Verified for G1 scope (automated evidence) — see Tests v2
A10: TM-REQ-007 | B10: Governance & outcomes | C10: Maintain source freshness and history | D10: P | E10: INT-27,INT-09 | F10: R1 | G10: G4 | H10: G4 | I10: FULL-SCOPE, LATER (G4) | J10: P1 | K10: Partial—gap remains | N10: TM-TST-007 | O10: Not verified — no build
A11: TM-REQ-008 | B11: Governance & outcomes | C11: Preserve a decision log and plan versions | D11: P | E11: INT-27,INT-09 | F11: R1 | G11: G3 | H11: G3 | I11: FIRST-BUILD (G1-G3) | J11: P1 | K11: Documented—implementation unverified | N11: TM-TST-008 | O11: Not verified — no build
A12: TM-REQ-009 | B12: Governance & outcomes | C12: Support no-deadline, paused and retired goals | D12: P | E12: INT-27,INT-09 | F12: R1 | G12: G3 | H12: G3 | I12: FIRST-BUILD (G1-G3) | J12: P1 | K12: Partial—gap remains | N12: TM-TST-009 | O12: Not verified — no build
A13: TM-REQ-010 | B13: Starting-point profile | C13: Progressive guided intake, not one giant form | D13: S | E13: INT-04,INT-10 | F13: R1 | G13: G1 | H13: G1 | I13: FIRST-BUILD (G1-G3) | J13: P0 | K13: Documented—implementation unverified | N13: TM-TST-010 | O13: Partial — automated part passes; manual/human gate pending — see Tests v2
A14: TM-REQ-011 | B14: Starting-point profile | C14: Personal identity, locale and time settings | D14: S | E14: INT-04,INT-10 | F14: R1 | G14: G1 | H14: G2 | I14: FIRST-BUILD (G1-G3) | J14: P1 | K14: Partial—gap remains | N14: TM-TST-011 | O14: Not verified — no build
A15: TM-REQ-012 | B15: Starting-point profile | C15: Education, experience and credentials | D15: S | E15: INT-04,INT-10 | F15: R1 | G15: G1 | H15: G3 | I15: FIRST-BUILD (G1-G3) | J15: P1 | K15: Documented—implementation unverified | N15: TM-TST-012 | O15: Not verified — no build
... A44: TM-REQ-041 | B44: Goal & execution engine | C44: Scheduling and habit supports are optional and non-punitive | D44: P | E44: INT-17,INT-26 | F44: R1 | G44: G3 | H44: G3 | I44: FIRST-BUILD (G1-G3) | J44: P1 | K44: Partial—gap remains | N44: TM-TST-041 | O44: Not verified — no build
A45: TM-REQ-042 | B45: Goal & execution engine | C45: Calendar integration is opt-in and reversible | D45: P | E45: INT-17,INT-26 | F45: R1 | G45: G6 | H45: G6 | I45: FULL-SCOPE, LATER (G6) | J45: P1 | K45: Partial—gap remains | L45: see 126 | N45: TM-TST-042 | O45: Not verified — no build
A46: TM-REQ-043 | B46: Goal & execution engine | C46: Weekly/monthly/quarterly reviews and reflection | D46: P | E46: INT-17,INT-26 | F46: R1 | G46: G3 | H46: G3 | I46: FIRST-BUILD (G1-G3) | J46: P1 | K46: Documented—implementation unverified | N46: TM-TST-043 | O46: Not verified — no build
A47: TM-REQ-044 | B47: Goal & execution engine | C47: Journal/voice notes are optional and sensitive | D47: P | E47: INT-17,INT-26 | F47: R1 | G47: G1 | H47: G7 | I47: FIRST-BUILD (G1-G3) | J47: P1 | K47: Partial—gap remains | N47: TM-TST-044 | O47: Not verified — no build
A48: TM-REQ-045 | B48: Goal & execution engine | C48: Real-life event capture triggers impact analysis | D48: P | E48: INT-17,INT-26 | F48: R0 | G48: G3 | H48: G3 | I48: FIRST-BUILD (G1-G3) | J48: P0 | K48: Documented—implementation unverified | N48: TM-TST-045 | O48: Not verified — no build
A49: TM-REQ-046 | B49: Goal & execution engine | C49: Preserve historical plan and compare alternatives | D49: P | E49: INT-17,INT-26 | F49: R1 | G49: G3 | H49: G3 | I49: FIRST-BUILD (G1-G3) | J49: P1 | K49: Documented—implementation unverified | N49: TM-TST-046 | O49: Not verified — no build
A50: TM-REQ-047 | B50: Goal & execution engine | C50: Overload, crisis and interruption modes | D50: B | E50: INT-17,INT-26 | F50: R0 | G50: G3 | H50: G3 | I50: FIRST-BUILD (G1-G3) | J50: P0 | K50: Partial—gap remains | N50: TM-TST-047 | O50: Not verified — no build
A51: TM-REQ-048 | B51: Goal & execution engine | C51: Do not infer task completion from untrusted sources alone | D51: P | E51: INT-17,INT-26 | F51: R1 | G51: G6 | H51: G6 | I51: FULL-SCOPE, LATER (G6) | J51: P1 | K51: Partial—gap remains | N51: TM-TST-048 | O51: Not verified — no build
A52: TM-REQ-049 | B52: Opportunity research & markets | C52: Research local and global markets with source provenance | D52: P | E52: INT-18,INT-31 | F52: R1 | G52: G4 | H52: G4 | I52: FULL-SCOPE, LATER (G4) | J52: P1 | K52: Documented—implementation unverified | N52: TM-TST-049 | O52: Not verified — no build
A53: TM-REQ-050 | B53: Opportunity research & markets | C53: Score demand, willingness to pay, competition and feasibility | D53: P | E53: INT-18,INT-31 | F53: R1 | G53: G4 | H53: G4 | I53: FULL-SCOPE, LATER (G4) | J53: P1 | K53: Documented—implementation unverified | N53: TM-TST-050 | O53: Not verified — no build
A54: TM-REQ-051 | B54: Opportunity research & markets | C54: Validate ideas with low-cost tests before major investment | D54: P | E54: INT-18,INT-31 | F54: R1 | G54: G4 | H54: G4 | I54: FULL-SCOPE, LATER (G4) | J54: P0 | K54: Documented—implementation unverified | N54: TM-TST-051 | O54: Not verified — no build
A55: TM-REQ-052 | B55: Opportunity research & markets | C55: Show evidence for and against; use base rates where defensible | D55: P | E55: INT-18,INT-31 | F55: R1 | G55: G4 | H55: G4 | I55: FULL-SCOPE, LATER (G4) | J55: P1 | K55: Partial—gap remains | N55: TM-TST-052 | O55: Not verified — no build
A56: TM-REQ-053 | B56: Opportunity research & markets | C56: Compare 2–3 strong options and let user save/customize/replace | D56: U | E56: INT-18,INT-31 | F56: R1 | G56: G4 | H56: G4 | I56: FULL-SCOPE, LATER (G4) | J56: P0 | K56: Documented—implementation unverified | N56: TM-TST-053 | O56: Not verified — no build
A57: TM-REQ-054 | B57: Opportunity research & markets | C57: Track price/offer/availability freshness and selected-option version | D57: P | E57: INT-18,INT-31 | F57: R1 | G57: G4 | H57: G4 | I57: FULL-SCOPE, LATER (G4) | J57: P1 | K57: Partial—gap remains | N57: TM-TST-054 | O57: Not verified — no build
... A72: TM-REQ-069 | B72: Visual-first UX | C72: Bangla/English quality and local conventions | D72: S | E72: INT-16,INT-04,INT-34 | F72: R1 | G72: G1 | H72: G2 | I72: FIRST-BUILD (G1-G3) | J72: P1 | K72: Partial—gap remains | N72: TM-TST-069 | O72: Not verified — no build
A73: TM-REQ-070 | B73: Visual-first UX | C73: Android-first, small screen, low bandwidth and optional desktop | D73: B | E73: INT-16,INT-04,INT-34 | F73: R1 | G73: G1 | H73: G2 | I73: FIRST-BUILD (G1-G3) | J73: P1 | K73: Partial—gap remains | M73: D-A | N73: TM-TST-070 | O73: Not verified — no build
A74: TM-REQ-071 | B74: Visual-first UX | C74: Use reminders without intrusive or shaming patterns | D74: P | E74: INT-16,INT-04,INT-34 | F74: R1 | G74: G2 | H74: G2 | I74: FIRST-BUILD (G1-G3) | J74: P1 | K74: Partial—gap remains | M74: D-A | N74: TM-TST-071 | O74: Not verified — no build
A75: TM-REQ-072 | B75: AI & research | C75: Keep canonical user data in the application database | D75: P | E75: INT-22,INT-35 | F75: R0 | G75: G1 | H75: G6 | I75: FIRST-BUILD (G1-G3) | J75: P0 | K75: Documented—implementation unverified | L75: see 083 (cross-link) | M75: D-C | N75: TM-TST-072 | O75: Not verified — no build
A76: TM-REQ-073 | B76: AI & research | C76: Use structured outputs and validated tools, not free-form action parsing | D76: P | E76: INT-22,INT-35 | F76: R0 | G76: G6 | H76: G6 | I76: FULL-SCOPE, LATER (G6) | J76: P0 | K76: Documented—implementation unverified | M76: D-C | N76: TM-TST-073 | O76: Not verified — no build
A77: TM-REQ-074 | B77: AI & research | C77: Keep model vs code responsibilities explicit | D77: P | E77: INT-22,INT-35 | F77: R0 | G77: G3 | H77: G3 | I77: FIRST-BUILD (G1-G3) | J77: P0 | K77: Documented—implementation unverified | N77: TM-TST-074 | O77: Not verified — no build
A78: TM-REQ-075 | B78: AI & research | C78: Treat web pages, PDFs, images and connector output as untrusted input | D78: P | E78: INT-22,INT-35 | F78: R0 | G78: G6 | H78: G6 | I78: FULL-SCOPE, LATER (G6) | J78: P0 | K78: Partial—gap remains | M78: D-C | N78: TM-TST-075 | O78: Not verified — no build
A79: TM-REQ-076 | B79: AI & research | C79: Cite sources, dates, confidence, conflict and unknowns | D79: P | E79: INT-22,INT-35 | F79: R1 | G79: G4 | H79: G4 | I79: FULL-SCOPE, LATER (G4) | J79: P1 | K79: Partial—gap remains | N79: TM-TST-076 | O79: Not verified — no build
A80: TM-REQ-077 | B80: AI & research | C80: Feature-specific provider retention and deletion mapping | D80: P | E80: INT-22,INT-35 | F80: R0 | G80: G6 | H80: G6 | I80: FULL-SCOPE, LATER (G6) | J80: P0 | K80: External verification required | M80: D-C | N80: TM-TST-077 | O80: Not verified — no build
A81: TM-REQ-078 | B81: AI & research | C81: Never expose API key in Android/browser client | D81: P | E81: INT-22,INT-35 | F81: R0 | G81: G6 | H81: G6 | I81: FULL-SCOPE, LATER (G6) | J81: P0 | K81: Documented—implementation unverified | M81: D-C | N81: TM-TST-078 | O81: Not verified — no build
A82: TM-REQ-079 | B82: AI & research | C82: Cost, quota, rate limits and offline mode stop uncontrolled calls | D82: P | E82: INT-22,INT-35 | F82: R0 | G82: G6 | H82: G6 | I82: FULL-SCOPE, LATER (G6) | J82: P0 | K82: Partial—gap remains | M82: D-C | N82: TM-TST-079 | O82: Not verified — no build
...

Sheet Tests v2
A1: TESTS v2 — measurable pass criteria (all 'Not run — specification stage')
A2: Replaces v1 boilerplate. Human-review = qualified-person gate. Negative claims use scans/property/red-team sets.
A3: Test ID | B3: Req ID | C3: R (v2) | D3: Gate (must pass before) | E3: Method | F3: Scenario / pass criterion (with threshold) | G3: Dataset / environment | H3: Blocked by decision | I3: Status | J3: Evidence link | K3: Defects
A4: TM-TST-001 | B4: TM-REQ-001 | C4: R0 | D4: G3 | E4: auto | F4: Given two metrics (net worth, annual revenue) with identical inputs, UI shows two distinct labelled measures; before any metric is chosen, 0 occurrences of a single 'trillionaire progress %' in rendered screens; every roadmap view shows its metric label. | G4: synthetic demo set (labelled) | I4: Not run — specification stage
A5: TM-TST-002 | B5: TM-REQ-002 | C5: R0 | D5: G3 | E5: auto | F5: Editing a revenue target changes 0 net-worth fields unless a user-created link exists; 20 random target edits leave unrelated targets unchanged. | G5: synthetic demo set (labelled) | I5: Not run — specification stage
A6: TM-TST-003 | B6: TM-REQ-003 | C6: R1 | D6: G3 | E6: auto | F6: With a hard 'prayer/family/rest' constraint set, scheduler places 0 tasks inside it across 100 generated plans; any attempt is flagged, never silent. | G6: synthetic demo set (labelled) | I6: Pass (G1) — G3 core: 100 generated plans, 0 tasks inside prayer/family/rest blocks, never over capacity, nothing silently dropped, deterministic | J6: tests/g3.test.ts; src/core/planner.ts
A7: TM-TST-004 | B7: TM-REQ-004 | C7: R0 | D7: G3 | E7: red-team | F7: 50 prompts/UI paths requesting guaranteed wealth or returns produce 0 guarantee statements (string scan) and 50/50 show an uncertainty note. | G7: adversarial prompt/input set (versioned) | I7: Not run — specification stage
A8: TM-TST-005 | B8: TM-REQ-005 | C8: R0 | D8: G1 | E8: auto | F8: With the historical 3-digit-taka starting figure unconfirmed, runway, emergency-fund and investment calculators return 'baseline needed' and 0 calculations read it (code search + test). | G8: synthetic demo set (labelled) | I8: Not run — specification stage
A9: TM-TST-006 | B9: TM-REQ-006 | C9: R0 | D9: G1 | E9: static-scan | F9: Every rendered value carries one label of FACT/ESTIMATE/INFERENCE/EXTERNAL/DEMO; 0 unlabelled values in a snapshot test over all screens. | G9: code/bundle/UI-string scan + synthetic data | I9: Pass (G1) — G1 automated: DOM audit of all 16 routes x 2 languages, 0 unlabelled values | J9: tests/g1.test.ts; evidence/screenshot-report.json
A10: TM-TST-007 | B10: TM-REQ-007 | C10: R1 | D10: G4 | E10: auto | F10: A cached item past its expiry shows a 'stale' badge in 100% of 20 cases; 'current' wording never appears for expired items. | G10: synthetic demo set (labelled) | I10: Not run — specification stage
A11: TM-TST-008 | B11: TM-REQ-008 | C11: R1 | D11: G3 | E11: auto | F11: Every plan change writes a DecisionLog row (what/why/approved-by/moved tasks) in 50/50 test changes. | G11: synthetic demo set (labelled) | I11: Not run — specification stage
A12: TM-TST-009 | B12: TM-REQ-009 | C12: R1 | D12: G3 | E12: auto | F12: A paused or retired goal generates 0 overdue reminders; its history remains readable. | G12: synthetic demo set (labelled) | I12: Not run — specification stage
A13: TM-TST-010 | B13: TM-REQ-010 | C13: R1 | D13: G1 | E13: usability | F13: 3 test users finish the minimum first-profile path in <=10 minutes; no screen shows more than 7 fields at once. | G13: test users with synthetic profile | I13: Partial (G1) — Structural check passes (max 7 fields/screen). 3-user timed usability session NOT run | J13: tests/g1.test.ts
A14: TM-TST-011 | B14: TM-REQ-011 | C14: R1 | D14: G2 | E14: auto | F14: Changing timezone re-renders schedules while stored event timestamps stay byte-identical (UTC) over 10 zones. | G14: synthetic demo set (labelled) | I14: Not run — specification stage
A15: TM-TST-012 | B15: TM-REQ-012 | C15: R1 | D15: G3 | E15: auto | F15: A path recommendation lists the profile entries it used; removing an entry changes the list. | G15: synthetic demo set (labelled) | I15: Not run — specification stage
A16: TM-TST-013 | B16: TM-REQ-013 | C16: R1 | D16: G3 | E16: auto | F16: Each target skill shows time/cost with stated assumptions; 100% of skill rows link to a goal. | G16: synthetic demo set (labelled) | I16: Not run — specification stage
A17: TM-TST-014 | B17: TM-REQ-014 | C17: R1 | D17: G3 | E17: auto | F17: Changing a preference recomputes recommendations and keeps the old preference in history (2 versions visible). | G17: synthetic demo set (labelled) | I17: Not run — specification stage
A18: TM-TST-015 | B18: TM-REQ-015 | C18: R1 | D18: G3 | E18: auto | F18: A plan needing more hours than the configured weekly capacity is flagged infeasible before scheduling in 20/20 cases. | G18: synthetic demo set (labelled) | I18: Not run — specification stage
A19: TM-TST-016 | B19: TM-REQ-016 | C19: R1 | D19: G3 | E19: auto | F19: Care/family time reduces capacity; third-party details never appear in any payload preview. | G19: synthetic demo set (labelled) | I19: Not run — specification stage
A20: TM-TST-017 | B20: TM-REQ-017 | C20: R1 | D20: G1 | E20: auto | F20: With every health field empty, all core flows complete; entered health fields are private by default. | G20: synthetic demo set (labelled) | I20: Pass (G1) — G1 automated: intake completes 100% with every health field empty; health fields private, per-item authorised | J20: tests/g1.test.ts
A21: TM-TST-018 | B21: TM-REQ-018 | C21: R1 | D21: G2 | E21: device | F21: On the target low-end Android profile, profile, goal and queue flows complete on a throttled 2G profile. | G21: real Android device matrix + synthetic data | I21: Not run — specification stage
A22: TM-TST-019 | B22: TM-REQ-019 | C22: R1 | D22: G4 | E22: human-review | F22: No opportunity can reach status 'legally cleared' without a recorded human review entry. | G22: review pack + synthetic data | I22: Not run — specification stage
A23: TM-TST-020 | B23: TM-REQ-020 | C23: R1 | D23: G3 | E23: auto | F23: Every inferred strength/weakness links to >=1 input and can be corrected; correction recomputes within one render. | G23: synthetic demo set (labelled) | I23: Not run — specification stage
A24: TM-TST-021 | B24: TM-REQ-021 | C24: R0 | D24: G1 | E24: auto | F24: Property test over all numeric fields: values 'unknown/later/NA/prefer-not' are never coerced to 0 or false in any calculation (1000 random cases). | G24: synthetic demo set (labelled) | I24: Pass (G1) — G1 automated: 1000-case property test + browser e2e (blank and 'don't know' never stored as 0) | J24: tests/g1.test.ts; tools/e2e.mjs; evidence/e2e-report.json
A25: TM-TST-022 | B25: TM-REQ-022 | C25: R1 | D25: G3 | E25: auto | F25: Net-worth total equals the sum of visible line items; estimated and stale lines are labelled. | G25: synthetic demo set (labelled) | I25: Partial (G1) — Money screen: net worth per scope from saved items, unknown stays unknown, nothing-entered shows 'nothing yet'. Real-user test not run | J25: tests/g3.test.ts; tests/money.test.ts; tools/e2e.mjs
A26: TM-TST-023 | B26: TM-REQ-023 | C26: R1 | D26: G3 | E26: auto | F26: 90-day cash-flow totals reconcile to entries; own-account transfers are excluded from income/expense (10 fixtures). | G26: synthetic demo set (labelled) | I26: Partial (G1) — Monthly cash flow on screen (one-off/yearly counted aside). 90-day review view not built | J26: tests/g3.test.ts; tests/money.test.ts
A27: TM-TST-024 | B27: TM-REQ-024 | C27: R1 | D27: G3 | E27: auto | F27: User can replace the budget template with a custom one; recommendation text cites why the template fits or not. | G27: synthetic demo set (labelled) | I27: Not run — specification stage
A28: TM-TST-025 | B28: TM-REQ-025 | C28: R1 | D28: G3 | E28: auto | F28: Four-bucket routing works as virtual buckets with no bank account required and no preset percentage forced. | G28: synthetic demo set (labelled) | I28: Not run — specification stage
A29: TM-TST-026 | B29: TM-REQ-026 | C29: R1 | D29: G3 | E29: auto | F29: Changing expense or income-volatility inputs recalculates the reserve range and shows the assumptions used. | G29: synthetic demo set (labelled) | I29: Not run — specification stage
A30: TM-TST-027 | B30: TM-REQ-027 | C30: R1 | D30: G3 | E30: auto | F30: Debt plan shows total cost and cash-flow effect; unclear terms raise an 'expert review' flag; interest-based items carry a halal-check flag. | G30: synthetic demo set (labelled) | I30: Not run — specification stage
A31: TM-TST-028 | B31: TM-REQ-028 | C31: R1 | D31: G3 | E31: auto | F31: A transfer between owned entities is counted once at group level; personal and business cash never merge silently. | G31: synthetic demo set (labelled) | I31: Not run — specification stage
A32: TM-TST-029 | B32: TM-REQ-029 | C32: R1 | D32: G3 | E32: auto | F32: Expansion scenario shows base and downside runway; unknown inputs stay ranges or blank. | G32: synthetic demo set (labelled) | I32: Not run — specification stage
A33: TM-TST-030 | B33: TM-REQ-030 | C33: R1 | D33: G4 | E33: red-team | F33: 40 prompts for return promises or product picks produce 0 return promises; risky or unclear products flagged; 0 transactions initiated. | G33: adversarial prompt/input set (versioned) | I33: Not run — specification stage
A34: TM-TST-031 | B34: TM-REQ-031 | C34: R1 | D34: G3 | E34: auto | F34: Valuation x ownership% is required before any valuation counts toward personal net worth; missing ownership shows 'unknown'. | G34: synthetic demo set (labelled) | I34: Not run — specification stage
A35: TM-TST-032 | B35: TM-REQ-032 | C35: R1 | D35: G4 | E35: human-review | F35: Obligations without a current sourced rule show 'verify'; no tax rate is hard-coded; reviewer sign-off recorded. | G35: review pack + synthetic data | I35: Not run — specification stage
A36: TM-TST-033 | B36: TM-REQ-033 | C36: R1 | D36: G4 | E36: human-review | F36: AML/source-of-funds notes link to a current official source; image text alone never sets an obligation. | G36: review pack + synthetic data | I36: Not run — specification stage
A37: TM-TST-034 | B37: TM-REQ-034 | C37: R0 | D37: G1 | E37: static-scan | F37: Inputs matching password/OTP/CVV/card patterns are rejected or redacted in 100% of 30 fixtures; 0 occurrences in logs, exports and analytics. | G37: code/bundle/UI-string scan + synthetic data | I37: Pass (G1) — G1 automated: 30 secret fixtures rejected, benign text allowed, 0 logging/network sinks in source, export redaction, browser rejection | J37: tests/g1.test.ts; tools/e2e.mjs; evidence/e2e-report.json
A38: TM-TST-035 | B38: TM-REQ-035 | C38: R0 | D38: G6 | E38: auto | F38: 0 money movements can start from generated text or a selected option; every payment needs an explicit confirm step (UI + API test). | G38: synthetic demo set (labelled) | I38: Not run — specification stage
A39: TM-TST-036 | B39: TM-REQ-036 | C39: R1 | D39: G3 | E39: auto | F39: User can enable/disable each life domain; dashboard re-balances with no data loss. | G39: synthetic demo set (labelled) | I39: Not run — specification stage
A40: TM-TST-037 | B40: TM-REQ-037 | C40: R1 | D40: G3 | E40: auto | F40: 100% of generated tasks link up to a goal; split/merge/delete keeps the links valid. | G40: synthetic demo set (labelled) | I40: Pass (G1) — G3 core: 200 random split/merge/delete ops, every task still reaches its goal, 0 orphans | J40: tests/g3.test.ts; src/core/goals.ts
...

Sheet Intent Register
A1: INTENT REGISTER — what the user wants, by origin
A2: U = user's own words (chat) · B = user-approved brief · S = source doc (second-hand) · P = later spec rule · I = assistant inference
A3: INT ID | B3: Intent | C3: Origin | D3: Source / date
A4: INT-01 | B4: Start from current situation; scale local → national → international; exactly when/how to go international | C4: U | D4: Earlier project prompt (excerpt A1; message cut off)
A5: INT-02 | B5: Continue earlier deep research from where it stopped | C5: U | D5: Excerpt A2
A6: INT-03 | B6: Tool first (goal-setting art/format), then profile, then data | C6: U | D6: Excerpt B1
A7: INT-04 | B7: Fields explain themselves; user need not remember what to give | C7: U | D7: Excerpt B1
A8: INT-05 | B8: Update/exception → click, go online, 2–3 best options; save, customize, change if reality differs | C8: U | D8: Excerpt B1
A9: INT-06 | B9: Muslim identity: ibadah, prayer, akhirah goals; namaz, zakat, hajj, roza, dan and more | C9: U | D9: Excerpt B2
A10: INT-07 | B10: Worldly trillion is pointless without akhirah — whole tool and all updates keep this in mind | C10: U | D10: Excerpt B2
A11: INT-08 | B11: Explain intent simply in an md file + a file of the user's exact words | C11: U | D11: Excerpt B4
A12: INT-09 | B12: Full product scope with phased build; MVP must not shrink scope; document reasons for any deferral | C12: B | D12: Brief attachment; Clarification v2 §7
A13: INT-10 | B13: No personal data now; demo data separate | C13: U+B | D13: B1; Clarification §3
A14: INT-11 | B14: Do not push decisions to the user; give default, reason, 2–3 options, costs | C14: B | D14: Brief attachment
... A39: INT-36 | B39: Specification work here; code build later in Claude Code | C39: B | D39: Chat 22 Oct 02:53–03:02 (accepted)

Sheet Gates
A1: BUILD GATES — full scope kept; gates decide order and proof
A2: A gate passes only with the listed evidence from the real build. Document existence never passes a gate.
A3: Gate | B3: Name | C3: Deliverables | D3: Pass evidence | E3: When
A4: G0 | B4: Spec freeze | C4: Canonical Spec + Register + Conflict/Deferral + visual register | D4: Every INT has >=1 REQ; 0 untraced REQ (script); owner written 'ok' | E4: Now
A5: G1 | B5: Safe shell + field catalog | C5: All modules (empty), phone design, field help, demo namespace, Capability Status, Deen/venture/assessment schema, One-Focus Home on demo data | D5: 100% fields have help+privacy class; empty-start test; demo→real impossible test; screenshot report | E5: After G0
A6: G2 | B6: Android offline prototype | C6: Local DB, queue, conflict, backup/restore, notifications; PWA vs native comparison | D6: Real-device airplane-mode, interrupted-sync, duplicate replay, clean-device restore — logs+video; device matrix | E6: After G1
A7: G3 | B7: Rule-based planner (≈80% without AI) | C7: Assessment, ladder, path fit, stage-gates+achievements, goals/habits, finance maths, capacity, reality-changed, overload, deen tracking (no scripture) | D7: Golden tests; unknown≠0 property test; constraint tests; usability study | E7: After G2
A8: G4 | B8: Research & options | C8: Click-consent research, option schema, save/customize/reject/own/replace, stale marks, library sources | D8: 0 network calls without click; <2 options → fewer; source+date on every option | E8: After G3
A9: G5 | B9: Deen content verification | C9: Scripture licence/completeness, prayer-time methods, zakat rule versions, Hajj official sources, halal-check flags | D9: Licence file; verse-count checks; scholar review note; UI-string scan (no score/fatwa) | E9: Before real Deen data
A10: G6 | B10: AI & automation | C10: Server-side proxy, tool scopes, cost caps, injection set, kill switch | D10: Red-team pass; 0 keys in client; spend-cap test | E10: Only after owner approves D-C
A11: G7 | B11: Privacy, recovery, real data | C11: Legal review, data-rights flows, incident runbook, full restore test | D11: Lawyer written review; clean-device restore; all R0 tests pass | E11: Before real sensitive data (or D-B device-only rule)
A12: G8 | B12: Pilot → PC → public decision | C12: Synthetic then approved real data; PC version; public-edition gate | D12: Regression report; actual vs predicted; tenant isolation if public | E12: After G7

Sheet Decisions
A1: DECISIONS — every default is UNAPPROVED until the owner says so
A2: Resolved-by-user rows come from the user's own words.
A3: ID | B3: Decision | C3: Why it matters | D3: Proposed default (unapproved) | E3: Options (pros/cons/cost) | F3: When needed | G3: State | H3: Safe work meanwhile
A4: D-A | B4: Technology: PWA vs native Android | C4: Offline storage, notifications, backup depend on it | D4: PWA-first (one codebase phone+PC) | E4: (1) PWA: ~free, one code, no store; risk: Android background limits · (2) Native Kotlin/Flutter: best OS fit; more time; store account fee (verify) · (3) PWA+Capacitor wrapper: middle | F4: Before G2 prototype | G4: APPROVED by owner, 22 Oct 2026 (PWA-first) | H4: Schema, field catalog, planner in portable TypeScript, UX
A5: D-B | B5: When real personal data may enter | C5: Matrix blocks real sensitive data until G7 legal review | D5: Device-only mode (no cloud/AI/sharing) after G3 + backup/restore pass — assistant proposal relaxing the matrix | E5: (1) Strict: wait for G7 · (2) Device-only after G3 (proposed) · (3) Cloud from start (risky; legal/cost) | F5: After G3 | G5: Open — needs owner approval | H5: G0–G3 all on synthetic data
A6: D-C | B6: AI provider and monthly spend cap | C6: API bill is separate; retention varies by feature | D6: No AI cost before G6 | E6: (1) OpenAI API · (2) Provider-agnostic layer (proposed) · (3) Rule-based only | F6: Before G6 | G6: Sequencing approved by user (AI later); provider/cap open | H6: Planner, research schema, tool contracts, regression set
A7: D-D | B7: Scripture/tafsir content source and licence | C7: Completeness and licence/offline rights unverified | D7: No scripture text shipped; references/links only | E7: (1) Licensed open text + attribution (verify) · (2) Online API only · (3) Deep-link to user's own Mushaf app | F7: Before G5 | G7: Open | H7: Prayer, fasting, zakat, giving, Hajj planning (no scripture text)
A8: D-E | B8: UI theme direction | C8: Visual identity affects design start | D8: Follow the user's previously chosen brand theme | E8: (1) Dark+gold premium (image refs) · (2) Existing brand theme · (3) Light neutral | F8: Before G1 design | G8: APPROVED by owner, 22 Oct 2026 (Ink & Paper theme) | H8: Structure, fields, flows are theme-neutral
A9: DEC-001 | B9: Define 'Trillionaire' metric | D9: Side-by-side metrics inside the tool (X1) | E9: Metric selector in tool | F9: In-tool | G9: Resolved by design — no owner decision needed now
A10: DEC-002 | B10: No personal data before tool ready | D10: — | E10: — | F10: — | G10: Confirmed (user)
A11: DEC-003 | B11: PWA vs native | D11: see D-A | G11: → D-A
A12: DEC-004 | B12: AI provider and cap | D12: see D-C | G12: → D-C
A13: DEC-005 | B13: Hosting, jurisdiction, legal review | D13: see D-B + G7 lawyer review | G13: → D-B / G7
A14: DEC-006 | B14: Madhhab/scholar preference | D14: Optional profile field | F14: At Deen profile | G14: Not needed now
A15: DEC-007 | B15: Scripture content licence | D15: see D-D | G15: → D-D
A16: DEC-008 | B16: Budget framework / four buckets | D16: Optional templates | G16: Safe default kept
A17: DEC-009 | B17: ERP integration boundary | D17: Standalone | G17: Resolved by user: business-neutral, ERP later optional
A18: DEC-010 | B18: Public SaaS vs private | D18: Private first | G18: Resolved by user: personal first, public later (G8)
A19: DEC-011 | B19: External integrations | D19: Off by default | F19: G6+ | G19: Safe default kept
A20: DEC-012 | B20: Location and prayer-time method | D20: Approximate region, user-chosen method | F20: Deen profile | G20: Not needed now
A21: DEC-013 | B21: Baseline confirmation (old figure) | D21: Historical/unverified | F21: Finance onboarding | G21: In-tool
A22: DEC-014 | B22: Automation permissions | D22: Per-action approval | F22: Before automation | G22: Safe default kept
A23: DEC-015 | B23: Offline content scope | D23: Core offline; AI/research online | F23: G2/G5 | G23: Safe default kept
A24: DEC-016 | B24: Productivity claims | D24: Exclude until verified | F24: Before copy | G24: Safe default kept
A25: DEC-017 | B25: Completion/release gate definition | D25: Evidence-based gates (this Register) | F25: Every gate | G25: Rule confirmed

Sheet Deferrals
A1: DEFERRALS — nothing dropped silently
A2: Each deferral has reason, dependency, target gate, who decided.
A3: ID | B3: Item | C3: Reason | D3: Dependency | E3: Target gate | F3: Decided by
A4: DF-01 | B4: PC/desktop version | C4: User: phone first | D4: Shared data/architecture from G1 | E4: G8 | F4: User (22 Oct)
A5: DF-02 | B5: Public Edition release | C5: User: personal first; public later | D5: Schema/templates in G1–G3; tenant isolation tests | E5: G8 (new approval) | F5: User (22 Oct)
A6: DF-03 | B6: AI integration | C6: User cannot set up AI now; design 80% AI-free | D6: AI interface contracts in G3; spend decision D-C | E6: G6 | F6: User (22 Oct)
A7: DF-04 | B7: External integrations (calendar, email, CRM, payment) | C7: Opt-in, scoped; depend on core | D7: Planner stable; D-C/DEC-011 | E7: G6+ | F7: Register default
A8: DF-05 | B8: Limited sharing (family/accountant) | C8: Not in any source; assistant inference | D8: Owner confirmation (INT-24) | E8: G8 | F8: Assistant — pending owner
A9: DF-06 | B9: 2D/3D visual extras | C9: P2; core visuals first | D9: Visual catalogue (MR-17) done | E9: G8 | F9: Register default
A10: DF-07 | B10: ERP integration | C10: User: business-neutral; ERP later optional | D10: Standalone core | E10: Unscheduled | F10: User
A11: DF-08 | B11: Scripture text inside the app | C11: Licence/completeness unverified | D11: D-D | E11: G5 | F11: Register default
A12: DF-09 | B12: Real sensitive data entry | C12: Privacy/recovery proof | D12: G7 or D-B device-only rule | E12: G7/G8 | F12: Register default
A13: DF-10 | B13: Franchise/SaaS productisation | C13: Needs internal repeatability | D13: Venture data + 2 gates passed | E13: G8 | F13: Source default

Sheet Conflicts
A1: CONFLICT REGISTER — contradictions and how they were resolved
A3: ID | B3: Item A | C3: Item B | D3: Resolution | E3: State
A4: X1 | B4: TM-REQ-001 test 'no roadmap from undefined metric' | C4: User: do not force decisions up front | D4: Side-by-side metrics, labelled roadmaps; no single trillion % before a metric is chosen | E4: Resolved in spec
A5: X2 | B5: TM-REQ-094 deletion right | C5: TM-REQ-008/046/125 history never lost | D5: History immutable until user asks to delete; then tombstone + minimal audit metadata (TM-REQ-156) | E5: Resolved in spec
A6: X3 | B6: TM-REQ-136 prototype-before-choice | C6: User: give default | D6: Declared default D-A (unapproved); prototype confirms | E6: Resolved in spec
A7: X4 | B7: TM-REQ-081 no continuous learning | C7: Context D9 recommendations update | D7: Wording: recalculation from saved data; no model training claim | E7: Resolved in spec
A8: X5 | B8: Earlier assistant 'MVP = gates 1–4, Deen later' | C8: Full scope + Deen day-one | D8: Full scope; Deen schema/privacy G1, content G5 | E8: Resolved
A9: X6 | B9: Earlier assistant 'tie to owner's business/ERP' | C9: Business-neutral | D9: Standalone, neutral library | E9: Resolved
A10: X7 | B10: Image advice 'outwork everyone, take massive risks' | C10: Capacity, worship, family limits | D10: Plans capped by capacity; no hustle advice in the tool | E10: Resolved
A11: X8 | B11: Matrix phases 0–4 vs Build Gates 0–8 | C11: — | D11: One vocabulary: G0–G8 only | E11: Resolved
A12: X9 | B12: Matrix P0 (71) vs audit P0 (10) | C12: Different scales | D12: R0/R1/R2 defined; audit severity kept separately | E12: Resolved

Sheet Visual Refs
A1: VISUAL REFERENCE REGISTER — 37 unique project images (ideas only; never copy figures/claims)
A2: All 37 viewed on 22 Oct 2026. Two files appear twice in the project listing.
A3: File (start) | B3: Title | C3: Group | D3: Idea to borrow | E3: Caution / verdict
A4: 17159b37… | B4: Claude, Explained Like You're 5 | C4: Tooling tips | D4: Not a product reference | E4: Out of scope
A5: 163bb133… | B5: How Billionaires Start & Scale | C5: Path/strategy | D5: Numbered 8-card layout; start small → scale | E5: Claims are conceptual
A6: b60b52ce… | B6: Billionaire in 100 Days | C6: Vision/hype | D6: Dashboard-card layout only | E6: Fabricated earnings; 'earn while you sleep' — never copy
A7: 5b4fa221… | B7: How to use Claude to start a business | C7: AI/tools | D7: 9-step flow, daily brief idea | E7: Tool-specific advice
A8: 256a0095… | B8: AI Systems: Human Analogy | C8: AI/tools | D8: LLM/RAG/MCP/agent explainer idea | E8: Educational
A9: 3a58f82e… | B9: How Billionaires Invest | C9: Money/investing | D9: Allocation-card layout | E9: Percentages unverified; halal-check needed
A10: de7b043b… | B10: Negotiate, Raise Capital, Build Wealth | C10: Path/strategy | D10: Three-pillar layout; capital paths | E10: Unverified
A11: 93f41d30… | B11: Royalties for Life | C11: Income | D11: Income-stream cards; create-once | E11: Unverified
A12: 8362d052… | B12: Intellectual Properties | C12: Income | D12: IP types & protect steps | E12: General info only
A13: 81e2335f… | B13: 10 Industries That Can Make You Rich | C13: Income | D13: Simple ranked list | E13: Not evidence-based
A14: 930e285c… | B14: The Dirty Money (AML flow) | C14: Money/compliance | D14: Flowchart with stages | E14: Legal claims unverified
... A40: dae4153b… | B40: Roadmap: Zero to Billion | C40: Path/strategy | D40: 4-phase path (Foundation, Credibility, Scaling, Wealth) | E40: Maps to gates G-A…G-H

Sheet Change Log
A1: CHANGE LOG v1.x → v2.0
A3: Type | B3: Change
A4: Added | B4: Origin, Intent link, R-priority, First/Must-pass gate, Scope tag, Blocked-by columns
A5: Added | B5: 31 new requirements TM-REQ-142…172 (MR-01…31): 23 from the audit gaps + 8 from the user's own 22 Oct statements
A6: Added | B6: 12 new intents INT-25…36 (user statements 22 Oct 02:24–03:02)
A7: Changed | B7: All 141 v1 tests replaced with measurable tests; v1 'Expected result' boilerplate removed
A8: Changed | B8: Phase vocabulary replaced by Gates G0–G8; 13 mixed-phase rows resolved to one first/must-pass value
A9: Changed | B9: Priority: R0/R1/R2 defined; v1 P0 (71) kept in history column
A10: Merged | B10: TM-REQ-135→126, TM-REQ-141→120 (rows kept, marked)
A11: Resolved | B11: Conflicts X1–X9; decisions D-A…D-E; deferrals DF-01…10
A12: Corrected | B12: Earlier estimate '≈158 requirements' superseded: actual 172 rows (170 active)
A13: Open | B13: Original 3 source documents not attached; Intent-link is domain-level default pending G0 refinement
